Workbook

Sheet Pivot Tables
A1: Row Labels | B1: Sum of Total Revenue | K1: Churn Reason | L1: Customer Status | M1: Sum of Total Revenue | N1: Sum of CLTV | O1: Lost Revenue | P1: Count Churn Reason | Q1: % of Churn Customers
A2: Churned | B2: 3690137.8 | D2: ="$ "&IF(B2>=1000000,ROUND(B2/1000000,2)&" Million",ROUND(B2/1000,0)&" Thousand") -> $ 3.69 Million | K2: Competitor made better offer | L2: Churned | M2: 583614.96 | N2: 1319961 | O2: 736346.04 | P2: 311 | Q2: =P2/$P$22 -> 0.16639914
A3: Joined | B3: 54496.45 | D3: ="$ "&IF(B3>=1000000,ROUND(B3/1000000,2)&" Million",ROUND(B3/1000,0)&" Thousand") -> $ 54 Thousand | K3: Competitor had better devices | L3: Churned | M3: 580848.73 | N3: 1297876 | O3: 717027.27 | P3: 313 | Q3: =P3/$P$22 -> 0.16746923
A4: Stayed | B4: 17654137 | D4: ="$ "&IF(B4>=1000000,ROUND(B4/1000000,2)&" Million",ROUND(B4/1000,0)&" Thousand") -> $ 17.65 Million | F4: Revenue | G4: CLTV | K4: Attitude of support person | L4: Churned | M4: 405099.47 | N4: 912013 | O4: 506913.53 | P4: 220 | Q4: =P4/$P$22 -> 0.11771001
A5: Grand Total | B5: 21398771 | D5: ="$ "&IF(B5>=1000000,ROUND(B5/1000000,2)&" Million",ROUND(B5/1000,0)&" Thousand") -> $ 21.4 Million | F5: =4207917.35/B5 -> 0.19664295 | G5: =2758350/B11 -> 0.08900406 | K5: Don't know | L5: Churned | M5: 256695.61 | N5: 518844 | O5: 262148.39 | P5: 130 | Q5: =P5/$P$22 -> 0.069555912
K6: Attitude of service provider | L6: Churned | M6: 175093.82 | N6: 394659 | O6: 219565.18 | P6: 94 | Q6: =P6/$P$22 -> 0.050294275
A7: Row Labels | B7: Sum of CLTV | K7: Competitor offered more data | L7: Churned | M7: 298170.99 | N7: 493394 | O7: 195223.01 | P7: 117 | Q7: =P7/$P$22 -> 0.062600321
A8: Churned | B8: 7755256 | D8: ="$ "&IF(B8>=1000000,ROUND(B8/1000000,2)&" Million",ROUND(B8/1000,0)&" Thousand") -> $ 7.76 Million | K8: Long distance charges | L8: Churned | M8: 97098.33 | N8: 269974 | O8: 172875.67 | P8: 64 | Q8: =P8/$P$22 -> 0.034242911
A9: Joined | B9: 1853534 | D9: ="$ "&IF(B9>=1000000,ROUND(B9/1000000,2)&" Million",ROUND(B9/1000,0)&" Thousand") -> $ 1.85 Million | K9: Competitor offered higher download speeds | L9: Churned | M9: 234601.57 | N9: 402057 | O9: 167455.43 | P9: 100 | Q9: =P9/$P$22 -> 0.053504548
A10: Stayed | B10: 21382493 | D10: ="$ "&IF(B10>=1000000,ROUND(B10/1000000,2)&" Million",ROUND(B10/1000,0)&" Thousand") -> $ 21.38 Million | K10: Price too high | L10: Churned | M10: 170537.17 | N10: 335804 | O10: 165266.83 | P10: 78 | Q10: =P10/$P$22 -> 0.041733547
A11: Grand Total | B11: 30991283 | D11: ="$ "&IF(B11>=1000000,ROUND(B11/1000000,2)&" Million",ROUND(B11/1000,0)&" Thousand") -> $ 30.99 Million | G11: Row Labels | H11: Min of Churn Score | K11: Network reliability | L11: Churned | M11: 132797.17 | N11: 291244 | O11: 158446.83 | P11: 72 | Q11: =P11/$P$22 -> 0.038523274
G12: Churned | H12: 65 | K12: Service dissatisfaction | L12: Churned | M12: 123176.52 | N12: 264385 | O12: 141208.48 | P12: 63 | Q12: =P12/$P$22 -> 0.033707865
A13: Customer ID | B13: Customer Status | C13: Sum of Total Revenue | D13: Sum of CLTV | E13: Sum of Churn Score | F13: Sum of Tenure in Months | G13: Joined | H13: 20 | K13: Product dissatisfaction | L13: Churned | M13: 205076.16 | N13: 325909 | O13: 120832.84 | P13: 77 | Q13: =P13/$P$22 -> 0.041198502
A14: 0004-TLHLJ | B14: Churned | C14: 415.45 | D14: 4479 | E14: 71 | F14: 4 | G14: Stayed | H14: 5 | K14: Limited range of services | L14: Churned | M14: 47291.21 | N14: 156823 | O14: 109531.79 | P14: 37 | Q14: =P14/$P$22 -> 0.019796683
A15: 0011-IGKFF | B15: Churned | C15: 1599.51 | D15: 3714 | E15: 91 | F15: 13 | G15: Grand Total | H15: 5 | K15: Lack of self-service on Website | L15: Churned | M15: 36858.83 | N15: 124551 | O15: 87692.17 | P15: 29 | Q15: =P15/$P$22 -> 0.015516319
A16: 0013-EXCHZ | B16: Churned | C16: 289.54 | D16: 3464 | E16: 68 | F16: 3 | K16: Moved | L16: Churned | M16: 93812.96 | N16: 174633 | O16: 80820.04 | P16: 46 | Q16: =P16/$P$22 -> 0.024612092
A17: 0022-TCJCI | B17: Churned | C17: 3271.65 | D17: 2654 | E17: 92 | F17: 45 | G17: Row Labels | H17: Min of Churn Score | I17: Average of Tenure in Months | K17: Poor expertise of online support | L17: Churned | M17: 56805.1 | N17: 128355 | O17: 71549.9 | P17: 31 | Q17: =P17/$P$22 -> 0.01658641
A18: 0023-HGHWL | B18: Churned | C18: 25.1 | D18: 5437 | E18: 85 | F18: 1 | G18: Churned | H18: 65 | I18: 17.979133 | K18: Lack of affordable download/upload speed | L18: Churned | M18: 66794.86 | N18: 126585 | O18: 59790.14 | P18: 30 | Q18: =P18/$P$22 -> 0.016051364
A19: 0023-XUOPT | B19: Churned | C19: 1781.88 | D19: 2973 | E19: 75 | F19: 13 | G19: Joined | H19: 20 | I19: 1.7202643 | K19: Extra data charges | L19: Churned | M19: 104334.14 | N19: 146482 | O19: 42147.86 | P19: 39 | Q19: =P19/$P$22 -> 0.020866774
A20: 0031-PVLZI | B20: Churned | C20: 126.07 | D20: 4133 | E20: 81 | F20: 4 | G20: Stayed | H20: 5 | I20: 41.041525 | K20: Poor expertise of phone support | L20: Churned | M20: 17257.35 | N20: 45932 | O20: 28674.65 | P20: 12 | Q20: =P20/$P$22 -> 0.0064205457
A21: 0032-PGELS | B21: Churned | C21: 30.5 | D21: 5171 | E21: 74 | F21: 1 | G21: Grand Total | H21: 5 | I21: 32.386767 | K21: Deceased | L21: Churned | M21: 4172.83 | N21: 25775 | O21: 21602.17 | P21: 6 | Q21: =P21/$P$22 -> 0.0032102729
A22: 0067-DKWBL | B22: Churned | C22: 179.08 | D22: 3475 | E22: 95 | F22: 2 | K22: Grand Total | M22: 3690137.8 | N22: 7755256 | O22: 4065118.2 | P22: 1869
A23: 0093-XWZFY | B23: Churned | C23: 5544.45 | D23: 2832 | E23: 93 | F23: 40
A24: 0094-OIFMO | B24: Churned | C24: 1367.79 | D24: 5980 | E24: 85 | F24: 11 | K24: Churn Reason | L24: Customer Status | M24: Lost Revenue | N24: Count Churn Reason
A25: 0107-WESLM | B25: Churned | C25: 51.62 | D25: 3874 | E25: 66 | F25: 1 | K25: Competitor made better offer | L25: Churned | M25: 736346.04 | N25: 311
A26: 0107-YHINA | B26: Churned | C26: 140.46 | D26: 4214 | E26: 93 | F26: 1 | K26: Competitor had better devices | L26: Churned | M26: 717027.27 | N26: 313
A27: 0112-QWPNC | B27: Churned | C27: 5997.3 | D27: 6452 | E27: 73 | F27: 49 | K27: Attitude of support person | L27: Churned | M27: 506913.53 | N27: 220
A28: 0115-TFERT | B28: Churned | C28: 3198.56 | D28: 4123 | E28: 89 | F28: 21 | K28: Grand Total | M28: 1960286.8 | N28: 844
A29: 0117-LFRMW | B29: Churned | C29: 1448.8 | D29: 3627 | E29: 80 | F29: 37 | K29: Churn Reason | L29: Lost Revenue | M29: % of Churn Customers
A30: 0122-OAHPZ | B30: Churned | C30: 724.62 | D30: 2473 | E30: 67 | F30: 7 | K30: Competitor made better offer | L30: 736346.04 | M30: =$P2/$P$22 -> 0.16639914
A31: 0125-LZQXK | B31: Churned | C31: 2242.75 | D31: 3025 | E31: 91 | F31: 15 | K31: Competitor had better devices | L31: 717027.27 | M31: =$P3/$P$22 -> 0.16746923
A32: 0133-BMFZO | B32: Churned | C32: 255.27 | D32: 3529 | E32: 94 | F32: 2 | K32: Attitude of support person | L32: 506913.53 | M32: =$P4/$P$22 -> 0.11771001
A33: 0135-NMXAP | B33: Churned | C33: 1224.96 | D33: 5671 | E33: 90 | F33: 12 | K33: Don't know | L33: 262148.39 | M33: =$P5/$P$22 -> 0.069555912
A34: 0137-OCGAB | B34: Churned | C34: 81.43 | D34: 3056 | E34: 90 | F34: 1 | K34: Attitude of service provider | L34: 219565.18 | M34: =$P6/$P$22 -> 0.050294275
A35: 0137-UDEUO | B35: Churned | C35: 141 | D35: 3398 | E35: 95 | F35: 3 | K35: Competitor offered more data | L35: 195223.01 | M35: =$P7/$P$22 -> 0.062600321
A36: 0148-DCDOS | B36: Churned | C36: 3234.1 | D36: 5641 | E36: 82 | F36: 25 | K36: Long distance charges | L36: 172875.67 | M36: =$P8/$P$22 -> 0.034242911
A37: 0151-ONTOV | B37: Churned | C37: 110.71 | D37: 4739 | E37: 78 | F37: 1 | K37: Competitor offered higher download speeds | L37: 167455.43 | M37: =$P9/$P$22 -> 0.053504548
A38: 0156-FVPTA | B38: Churned | C38: 1751.98 | D38: 5102 | E38: 87 | F38: 22 | K38: Price too high | L38: 165266.83 | M38: =$P10/$P$22 -> 0.041733547
A39: 0193-ESZXP | B39: Churned | C39: 7188.02 | D39: 5067 | E39: 91 | F39: 58 | K39: Network reliability | L39: 158446.83 | M39: =$P11/$P$22 -> 0.038523274
A40: 0195-IESCP | B40: Churned | C40: 975.5 | D40: 3573 | E40: 75 | F40: 10
...

Sheet Customer Churn Analysis Report
A1: Customer Churn Analysis
A3: Revenue at Risk Due to Churn | P3: Contract Types causing most Churn
I4: Churned : | L4: ='Pivot Tables'!D2 -> $ 3.69 Million
I7: Joined : | L7: ='Pivot Tables'!D3 -> $ 54 Thousand
I10: Stay : | L10: ='Pivot Tables'!D4 -> $ 17.65 Million
A14: Customer Life Time Value at Risk Due to Churn
A15: Churned : | D15: ='Pivot Tables'!D8 -> $ 7.76 Million
A18: Joined : | D18: ='Pivot Tables'!D9 -> $ 1.85 Million
P20: Internet Types causing most Churn
A21: Stay : | D21: ='Pivot Tables'!D10 -> $ 21.38 Million | P21: Internet Type | R21: % of Total Churned Revenue | U21: % of Total Churned Customers
P24: Fibre Optic | R24: ='Pivot Tables'!$L$71 -> 0.8199041 | U24: ='Pivot Tables'!$K$71 -> 0.66131621
A25: Customers Representing Highest Future Value at Risk
A26: Current Customers | P26: DSL | R26: ='Pivot Tables'!$L$72 -> 0.084811172 | U26: ='Pivot Tables'!$K$72 -> 0.16425896
A27: No. of Customers | C27: Revenue | E27: CLTV | G27: Average Churn Score | I27: Average Tenure | K27: % of Total Revenue | M27: % of Total CLTV
P28: Cable | R28: ='Pivot Tables'!$L$73 -> 0.083576235 | U28: ='Pivot Tables'!$K$73 -> 0.11396469
A31: ='Risk - Unchurned Customer'!$H$13 -> 446 | C31: ='Risk - Unchurned Customer'!$I$7 -> $ 3.02 Million | E31: ='Risk - Unchurned Customer'!$I$8 -> $ 2.09 Million | G31: ='Risk - Unchurned Customer'!$H$9 -> 72.311659 | I31: ='Risk - Unchurned Customer'!$H$10 -> 57.82287 | K31: ='Risk - Unchurned Customer'!$H$11 -> 0.14122263 | M31: ='Risk - Unchurned Customer'!$H$12 -> 0.06751876
P33: Services with the least Churn
A34: Churned Customers
A35: No. of Customers | C35: Revenue | E35: CLTV | G35: Average Churn Score | I35: Average Tenure | K35: % of Total Revenue | M35: % of Total CLTV
A39: ='Risk - Churned Customer'!$H$13 -> 1869 | C39: ='Risk - Churned Customer'!$I$7 -> $ 3.69 Million | E39: ='Risk - Churned Customer'!$I$8 -> $ 7.76 Million | G39: ='Risk - Churned Customer'!$H$9 -> 81.777956 | I39: ='Risk - Churned Customer'!$H$10 -> 17.979133 | K39: ='Risk - Churned Customer'!$H$11 -> 0.17244625 | M39: ='Risk - Churned Customer'!$H$12 -> 0.25023991
A42: Total
A43: Total Customers | C43: Total Revenue | F43: Total CLTV | I43: % of Total Revenue | L43: % of Total CLTV
A46: =A31+A39 -> 2315 | C46: ="$ "&ROUND(SUM('Risk - Unchurned Customer'!$H$7,'Risk - Churned Customer'!$H$7)/1000000,2)&" Million" -> $ 6.71 Million | F46: ="$ "&ROUND(SUM('Risk - Unchurned Customer'!$H$8,'Risk - Churned Customer'!$H$8)/1000000,2)&" Million" -> $ 9.85 Million | I46: =SUM('Risk - Unchurned Customer'!$H$7,'Risk - Churned Customer'!$H$7)/'Pivot Tables'!$B$5 -> 0.31366888 | L46: =SUM('Risk - Unchurned Customer'!$H$8,'Risk - Churned Customer'!$H$8)/'Pivot Tables'!$B$11 -> 0.31775867
A49: Churn Reasons costing most Revenue
A50: Sl No. | B50: Top 3 Churn Reasons | F50: % of All Churn Reasons | K50: Lost Revenue
A53: 1 | B53: Competitor made Better Offer | F53: ='Pivot Tables'!$P$2/'Pivot Tables'!$P$22 -> 0.16639914 | K53: ='Pivot Tables'!$O$2 -> 736346.04
A55: 2 | B55: Competitor had Better Devices | F55: ='Pivot Tables'!$P$3/'Pivot Tables'!$P$22 -> 0.16746923 | K55: ='Pivot Tables'!$O$3 -> 717027.27
P56: Cities Generating Most Value
A57: 3 | B57: Attitude of Support Person | F57: ='Pivot Tables'!$P$4/'Pivot Tables'!$P$22 -> 0.11771001 | K57: ='Pivot Tables'!$O$4 -> 506913.53
A59: Total | F59: =SUM('Pivot Tables'!$P$2:$P$4)/'Pivot Tables'!$P$22 -> 0.45157838 | K59: ="$ "&ROUND(SUM($K$53:$N$58)/1000000,2)&" Million" -> $ 1.96 Million
A61: % of Total Lost Revenue to Customer Churn | K61: =SUM($K$53:$N$58)/'Pivot Tables'!$O$22 -> 0.48222136
P73: % Revenue of Total Revenue | W73: % CLTV of Total CLTV
P76: ='Pivot Tables'!$I$112/'Pivot Tables'!$B$5 -> 0.15903199 | W76: ='Pivot Tables'!$J$112/'Pivot Tables'!$B$11 -> 0.16334648

Sheet Risk - Unchurned Customer
A1: Customer ID | B1: Total Revenue from Customer | C1: Sum of CLTV | D1: Customer Churn Score | E1: Customer Tenure (Months) | G1: Criteria
A2: 0036-IHMOT | B2: 7603.95 | C2: 5892 | D2: 65 | E2: 55 | G2: Customer Status: Joined, Stayed
A3: 0078-XZMHT | B3: 8646.12 | C3: 6322 | D3: 76 | E3: 72 | G3: Total Revenue > CLTV
A4: 0083-PIVIK | B4: 5958.91 | C4: 4761 | D4: 67 | E4: 64 | G4: Churn Score >= Min Churn Score
A5: 0103-CSITQ | B5: 6709.27 | C5: 6026 | D5: 65 | E5: 57 | G5: Tenure > Average Tenure before churn
A6: 0134-XWXCE | B6: 3625.64 | C6: 3253 | D6: 71 | E6: 44
A7: 0147-ESWWR | B7: 4735 | C7: 3172 | D7: 77 | E7: 39 | G7: Total Revenue | H7: =SUM(B2:B10000) -> 3021990.7 | I7: ="$ "&ROUND(H7/1000000,2)&" Million" -> $ 3.02 Million
A8: 0164-APGRB | B8: 11979.34 | C8: 4589 | D8: 69 | E8: 72 | G8: Total CLTV | H8: =SUM(C2:C10000) -> 2092493 | I8: ="$ "&ROUND(H8/1000000,2)&" Million" -> $ 2.09 Million
A9: 0178-SZBHO | B9: 4068.68 | C9: 3760 | D9: 76 | E9: 47 | G9: Average Churn Score | H9: =AVERAGE(D2:D10000) -> 72.311659
A10: 0201-MIBOL | B10: 7161.55 | C10: 4861 | D10: 69 | E10: 66 | G10: Average Tenure | H10: =AVERAGE(E2:E10000) -> 57.82287
A11: 0206-TBWLC | B11: 6665.1 | C11: 4488 | D11: 67 | E11: 54 | G11: Percent of Total Revenue | H11: =H7/'Pivot Tables'!B5 -> 0.14122263
A12: 0244-LGNFY | B12: 8893 | C12: 6342 | D12: 75 | E12: 72 | G12: Percent of Total CLTV | H12: =H8/'Pivot Tables'!B11 -> 0.06751876
A13: 0248-PGHBZ | B13: 6313.04 | C13: 5857 | D13: 80 | E13: 67 | G13: Total Customers at risk of Churning | H13: =COUNTA(A2:A10000) -> 446
A14: 0266-GMEAO | B14: 9206.23 | C14: 5879 | D14: 70 | E14: 72
A15: 0270-THENM | B15: 7170.23 | C15: 6233 | D15: 77 | E15: 72
A16: 0334-ZFJSR | B16: 5602.53 | C16: 5501 | D16: 68 | E16: 55
A17: 0392-BZIUW | B17: 8063.56 | C17: 5678 | D17: 70 | E17: 72
A18: 0419-YAAPX | B18: 4994.24 | C18: 4696 | D18: 71 | E18: 49
A19: 0420-TXVSG | B19: 6917.31 | C19: 5933 | D19: 73 | E19: 66
A20: 0434-CSFON | B20: 6500.15 | C20: 4488 | D20: 70 | E20: 47
A21: 0440-EKDCF | B21: 5842.6 | C21: 4404 | D21: 80 | E21: 62
A22: 0459-SPZHJ | B22: 6282.35 | C22: 4652 | D22: 75 | E22: 63
A23: 0471-ARVMX | B23: 7722.78 | C23: 5061 | D23: 68 | E23: 62
A24: 0481-SUMCB | B24: 6270.75 | C24: 5391 | D24: 69 | E24: 45
A25: 0516-UXRMT | B25: 7250.57 | C25: 5801 | D25: 71 | E25: 62
... A447: 9978-HYCIN | B447: 6085.68 | C447: 3384 | D447: 68 | E447: 47

Sheet Risk - Churned Customer
A1: Customer ID | B1: Total Revenue from Customer | C1: Sum of CLTV | D1: Customer Churn Score | E1: Customer Tenure (Months) | G1: Criteria
A2: 0004-TLHLJ | B2: 415.45 | C2: 4479 | D2: 71 | E2: 4 | G2: Customer Status: Churned
A3: 0011-IGKFF | B3: 1599.51 | C3: 3714 | D3: 91 | E3: 13
A4: 0013-EXCHZ | B4: 289.54 | C4: 3464 | D4: 68 | E4: 3
A5: 0022-TCJCI | B5: 3271.65 | C5: 2654 | D5: 92 | E5: 45
A6: 0023-HGHWL | B6: 25.1 | C6: 5437 | D6: 85 | E6: 1
A7: 0023-XUOPT | B7: 1781.88 | C7: 2973 | D7: 75 | E7: 13 | G7: Total Revenue | H7: =SUM(B2:B9999) -> 3690137.8 | I7: ="$ "&ROUND(H7/1000000,2)&" Million" -> $ 3.69 Million
A8: 0031-PVLZI | B8: 126.07 | C8: 4133 | D8: 81 | E8: 4 | G8: Total CLTV | H8: =SUM(C2:C9999) -> 7755256 | I8: ="$ "&ROUND(H8/1000000,2)&" Million" -> $ 7.76 Million
A9: 0032-PGELS | B9: 30.5 | C9: 5171 | D9: 74 | E9: 1 | G9: Average Churn Score | H9: =AVERAGE(D2:D9999) -> 81.777956
A10: 0067-DKWBL | B10: 179.08 | C10: 3475 | D10: 95 | E10: 2 | G10: Average Tenure | H10: =AVERAGE(E2:E9999) -> 17.979133
A11: 0093-XWZFY | B11: 5544.45 | C11: 2832 | D11: 93 | E11: 40 | G11: Percent of Total Revenue | H11: =H7/'Pivot Tables'!B5 -> 0.17244625
A12: 0094-OIFMO | B12: 1367.79 | C12: 5980 | D12: 85 | E12: 11 | G12: Percent of Total CLTV | H12: =H8/'Pivot Tables'!B11 -> 0.25023991
A13: 0107-WESLM | B13: 51.62 | C13: 3874 | D13: 66 | E13: 1 | G13: Total Customers at risk of Churning | H13: =COUNTA(A2:A9999) -> 1869
A14: 0107-YHINA | B14: 140.46 | C14: 4214 | D14: 93 | E14: 1
A15: 0112-QWPNC | B15: 5997.3 | C15: 6452 | D15: 73 | E15: 49
A16: 0115-TFERT | B16: 3198.56 | C16: 4123 | D16: 89 | E16: 21
A17: 0117-LFRMW | B17: 1448.8 | C17: 3627 | D17: 80 | E17: 37
A18: 0122-OAHPZ | B18: 724.62 | C18: 2473 | D18: 67 | E18: 7
A19: 0125-LZQXK | B19: 2242.75 | C19: 3025 | D19: 91 | E19: 15
A20: 0133-BMFZO | B20: 255.27 | C20: 3529 | D20: 94 | E20: 2
A21: 0135-NMXAP | B21: 1224.96 | C21: 5671 | D21: 90 | E21: 12
A22: 0137-OCGAB | B22: 81.43 | C22: 3056 | D22: 90 | E22: 1
A23: 0137-UDEUO | B23: 141 | C23: 3398 | D23: 95 | E23: 3
A24: 0148-DCDOS | B24: 3234.1 | C24: 5641 | D24: 82 | E24: 25
A25: 0151-ONTOV | B25: 110.71 | C25: 4739 | D25: 78 | E25: 1
... A1870: 9992-RRAMN | B1870: 2230.1 | C1870: 5248 | D1870: 68 | E1870: 22
